Workbook

Sheet AV 1
B2: GUIA PORTAGE DE EDUCAÇÃO PRÉ-ESCOLAR
B4: Nome: | C4: ESTER BERNARDINO PEREIRA
B5: Idade: | C5: 2
B6: Avaliador: | C6: AVELINA
B7: Data da Avaliação: | C7: 46074
B9: * Nas tabelas abaixo, insira apenas SIM, NÃO, ÀS VEZES e NA (se Não Avaliado) QUE CONSTAM NA LISTA DE OPÇÕES DE CADA CÉLULA. Não digite texto algum, apenas selecione a opção da lista. Os totais e pontos são automáticos.
B10: Legendas: Sim (alcançou): 1 pto | N – Não - ainda não alcançou: 0 pto | AV - Às vezes: 0,5 ptos | NA: Não Avaliado | Total de Acertos = Pontuação Total. Não deixe espaços vazios. Se o item não foi avaliado, marque a opção NA.
B11: SOCIALIZAÇÃO | E11: LINGUAGEM | H11: COGNIÇÃO | K11: AUTOCUIDADOS | N11: DESENVOLVIMENTO MOTOR
B12: Socialização - 0 a 1 ano | C12: Sim/Não/Às vezes | D12: Ptos | E12: Linguagem – 0 a 1 anos | F12: Sim/Não/Às vezes | G12: Ptos | H12: Cognição – 0 a 1 ano | I12: Sim/Não/Às vezes | J12: Ptos | K12: Auto cuidados – 0 a 1 anos | L12: Sim/Não/Às vezes | M12: Ptos | N12: Desenvolvimento Motor – 0 a 1 ano | O12: Sim/Não/Às vezes | P12: Ptos
B13: 01 Observa uma pessoa movimentando-se em seu campo visual. | D13: =IF(C13="Sim",1,IF(C13="Não",0,IF(C13="Às vezes",0.5,"-"))) -> - | E13: 01 Repete sons emitidos por outras pessoas. | G13: =IF(F13="Sim",1,IF(F13="Não",0,IF(F13="Às vezes",0.5,"-"))) -> - | H13: 01 Remove um pano do rosto que obscureça sua visão. | J13: =IF(I13="Sim",1,IF(I13="Não",0,IF(I13="Às vezes",0.5,"-"))) -> - | K13: 01 Suga e deglute líquidos. | M13: =IF(L13="Sim",1,IF(L13="Não",0,IF(L13="Às vezes",0.5,"-"))) -> - | N13: 01 Alcança um objeto colocado à sua frente (15 a 20 cm.). | P13: =IF(O13="Sim",1,IF(O13="Não",0,IF(O13="Às vezes",0.5,"-"))) -> -
B14: 02 Sorri em resposta à atenção do adulto | D14: =IF(C14="Sim",1,IF(C14="Não",0,IF(C14="Às vezes",0.5,"-"))) -> - | E14: 02 Repete a mesma sílaba 2 a 3 vezes. | G14: =IF(F14="Sim",1,IF(F14="Não",0,IF(F14="Às vezes",0.5,"-"))) -> - | H14: 02 Procura com o olhar um objeto que foi tirado de seu campo visual. | J14: =IF(I14="Sim",1,IF(I14="Não",0,IF(I14="Às vezes",0.5,"-"))) -> - | K14: 02 Toma mingau / sopinha. | M14: =IF(L14="Sim",1,IF(L14="Não",0,IF(L14="Às vezes",0.5,"-"))) -> - | N14: 02 Apanha um objeto colocado à sua frente (8 cm.). | P14: =IF(O14="Sim",1,IF(O14="Não",0,IF(O14="Às vezes",0.5,"-"))) -> -
B15: 03 Vocaliza em resposta à atenção | D15: =IF(C15="Sim",1,IF(C15="Não",0,IF(C15="Às vezes",0.5,"-"))) -> - | E15: 03 Responde a gestos com gestos. | G15: =IF(F15="Sim",1,IF(F15="Não",0,IF(F15="Às vezes",0.5,"-"))) -> - | H15: 03 Remove um objeto de um recipiente colocando a mão dentro do mesmo | J15: =IF(I15="Sim",1,IF(I15="Não",0,IF(I15="Às vezes",0.5,"-"))) -> - | K15: 03 Estende as mãos em direção a mamadeira, tentando pegá-la | M15: =IF(L15="Sim",1,IF(L15="Não",0,IF(L15="Às vezes",0.5,"-"))) -> - | N15: 03 Estende os braços em direção a um objeto à sua frente e o apanha. | P15: =IF(O15="Sim",1,IF(O15="Não",0,IF(O15="Às vezes",0.5,"-"))) -> -
B16: 04 Olha para sua própria mão, sorrindo ou vocalizando | D16: =IF(C16="Sim",1,IF(C16="Não",0,IF(C16="Às vezes",0.5,"-"))) -> - | E16: 04 Obedece a uma ordem simples, quando acompanhada de gestos indicativos. | G16: =IF(F16="Sim",1,IF(F16="Não",0,IF(F16="Às vezes",0.5,"-"))) -> - | H16: 04 Coloca um objeto em um recipiente imitando um adulto. | J16: =IF(I16="Sim",1,IF(I16="Não",0,IF(I16="Às vezes",0.5,"-"))) -> - | K16: 04 Come alimentos liquidificados dados pelos pais. | M16: =IF(L16="Sim",1,IF(L16="Não",0,IF(L16="Às vezes",0.5,"-"))) -> - | N16: 04 Alcança um objeto preferido. | P16: =IF(O16="Sim",1,IF(O16="Não",0,IF(O16="Às vezes",0.5,"-"))) -> -
B17: 05 Responde a seu círculo familiar, sorrindo, vocalizando ou parando de chorar | D17: =IF(C17="Sim",1,IF(C17="Não",0,IF(C17="Às vezes",0.5,"-"))) -> - | E17: 05 Interrompe a atividade quando lhe dizem "Não" 75% das vezes. | G17: =IF(F17="Sim",1,IF(F17="Não",0,IF(F17="Às vezes",0.5,"-"))) -> - | H17: 05 Coloca um objeto em um recipiente quando recebe instruções. | J17: =IF(I17="Sim",1,IF(I17="Não",0,IF(I17="Às vezes",0.5,"-"))) -> - | K17: 05 Segura a mamadeira sem ajuda enquanto bebe. | M17: =IF(L17="Sim",1,IF(L17="Não",0,IF(L17="Às vezes",0.5,"-"))) -> - | N17: 05 Coloca objetos na boca. | P17: =IF(O17="Sim",1,IF(O17="Não",0,IF(O17="Às vezes",0.5,"-"))) -> -
B18: 06 Sorri em resposta à expressão facial dos outros. | D18: =IF(C18="Sim",1,IF(C18="Não",0,IF(C18="Às vezes",0.5,"-"))) -> - | E18: 06 Responde a perguntas simples com respostas não verbais. | G18: =IF(F18="Sim",1,IF(F18="Não",0,IF(F18="Às vezes",0.5,"-"))) -> - | H18: 06 Balança um brinquedo que produz som, pendurado em um barbante. | J18: =IF(I18="Sim",1,IF(I18="Não",0,IF(I18="Às vezes",0.5,"-"))) -> - | K18: 06 Leva a mamadeira até a boca ou a recusa, empurrando-a | M18: =IF(L18="Sim",1,IF(L18="Não",0,IF(L18="Às vezes",0.5,"-"))) -> - | N18: 06 Eleva a cabeça e o tronco apoiando-se nos braços, ao estar deitado de barriga para baixo. | P18: =IF(O18="Sim",1,IF(O18="Não",0,IF(O18="Às vezes",0.5,"-"))) -> -
B19: 07 Sorri e vocaliza ao ver sua imagem no espelho | D19: =IF(C19="Sim",1,IF(C19="Não",0,IF(C19="Às vezes",0.5,"-"))) -> - | E19: 07 Combina 2 sílabas diferentes quando tenta verbalizar. | G19: =IF(F19="Sim",1,IF(F19="Não",0,IF(F19="Às vezes",0.5,"-"))) -> - | H19: 07 Coloca três objetos em um recipiente e o esvazia. | J19: =IF(I19="Sim",1,IF(I19="Não",0,IF(I19="Às vezes",0.5,"-"))) -> - | K19: 07 Come alimentos amassados dados pelos pais. | M19: =IF(L19="Sim",1,IF(L19="Não",0,IF(L19="Às vezes",0.5,"-"))) -> - | N19: 07 Levanta a cabeça e o tronco apoiando-se em um só braço. | P19: =IF(O19="Sim",1,IF(O19="Não",0,IF(O19="Às vezes",0.5,"-"))) -> -
B20: 08 Acaricia ou toca no rosto de adultos (puxa cabelo, nariz, óculos, etc.). | D20: =IF(C20="Sim",1,IF(C20="Não",0,IF(C20="Às vezes",0.5,"-"))) -> - | E20: 08 Imita padrões de entonação da voz de outras pessoas. | G20: =IF(F20="Sim",1,IF(F20="Não",0,IF(F20="Às vezes",0.5,"-"))) -> - | H20: 08 Transfere um objeto de uma mão à outra para apanhar outro objeto. | J20: =IF(I20="Sim",1,IF(I20="Não",0,IF(I20="Às vezes",0.5,"-"))) -> - | K20: 08 Bebe em uma caneca, segurada pelos pais. | M20: =IF(L20="Sim",1,IF(L20="Não",0,IF(L20="Às vezes",0.5,"-"))) -> - | N20: 08 Toca e explora objetos com a boca. | P20: =IF(O20="Sim",1,IF(O20="Não",0,IF(O20="Às vezes",0.5,"-"))) -> -
B21: 09 Estende a mão em direção a um objeto oferecido. | D21: =IF(C21="Sim",1,IF(C21="Não",0,IF(C21="Às vezes",0.5,"-"))) -> - | E21: 09 Usa uma palavra funcionalmente para indicar objetos ou pessoas. | G21: =IF(F21="Sim",1,IF(F21="Não",0,IF(F21="Às vezes",0.5,"-"))) -> - | H21: 09 Deixa cair e apanha um brinquedo. | J21: =IF(I21="Sim",1,IF(I21="Não",0,IF(I21="Às vezes",0.5,"-"))) -> - | K21: 09 Come alimentos semissólidos dados pelos pais. | M21: =IF(L21="Sim",1,IF(L21="Não",0,IF(L21="Às vezes",0.5,"-"))) -> - | N21: 09 Em DV (decúbito ventral, de bruços), vira de lado e mantém esta posição ½ das vezes. | P21: =IF(O21="Sim",1,IF(O21="Não",0,IF(O21="Às vezes",0.5,"-"))) -> -
B22: 10 Estende os braços em direção a pessoas familiares | D22: =IF(C22="Sim",1,IF(C22="Não",0,IF(C22="Às vezes",0.5,"-"))) -> - | E22: 10 Vocaliza em resposta à fala de outras pessoas. | G22: =IF(F22="Sim",1,IF(F22="Não",0,IF(F22="Às vezes",0.5,"-"))) -> - | H22: 10 Descobre um objeto escondido sob um recipiente. | J22: =IF(I22="Sim",1,IF(I22="Não",0,IF(I22="Às vezes",0.5,"-"))) -> - | K22: 10 Alimenta-se sozinho usando os dedos. | M22: =IF(L22="Sim",1,IF(L22="Não",0,IF(L22="Às vezes",0.5,"-"))) -> - | N22: 10 Em DV, vira de costas. | P22: =IF(O22="Sim",1,IF(O22="Não",0,IF(O22="Às vezes",0.5,"-"))) -> -
B23: 11 Estende a mão e toca sua imagem refletida no espelho. | D23: =IF(C23="Sim",1,IF(C23="Não",0,IF(C23="Às vezes",0.5,"-"))) -> - | E23: Total de Acertos | F23: =SUM(G13:G22) -> 0 | H23: 11 Empurra 3 blocos como se fosse um comboio. | J23: =IF(I23="Sim",1,IF(I23="Não",0,IF(I23="Às vezes",0.5,"-"))) -> - | K23: 11 Segura a caneca com ambas as mãos e bebe. | M23: =IF(L23="Sim",1,IF(L23="Não",0,IF(L23="Às vezes",0.5,"-"))) -> - | N23: 11 Em DV, move-se para frente o equivalente à sua altura. | P23: =IF(O23="Sim",1,IF(O23="Não",0,IF(O23="Às vezes",0.5,"-"))) -> -
B24: 12 Segura e examina por 1 minuto um objeto que lhe foi dado. | D24: =IF(C24="Sim",1,IF(C24="Não",0,IF(C24="Às vezes",0.5,"-"))) -> - | E24: Linguagem – 1 a 2 anos | H24: 12 Remove um círculo de uma prancha, por imitação. | J24: =IF(I24="Sim",1,IF(I24="Não",0,IF(I24="Às vezes",0.5,"-"))) -> - | K24: 12 Leva a colher cheia de comida até a boca com ajuda. | M24: =IF(L24="Sim",1,IF(L24="Não",0,IF(L24="Às vezes",0.5,"-"))) -> - | N24: 12 Em DD (decúbito dorsal), rola para o lado. | P24: =IF(O24="Sim",1,IF(O24="Não",0,IF(O24="Às vezes",0.5,"-"))) -> -
B25: 13 Sacode ou aperta um objeto colocado em sua mão, produzindo sons involuntários. | D25: =IF(C25="Sim",1,IF(C25="Não",0,IF(C25="Às vezes",0.5,"-"))) -> - | E25: 11 Diz 5 palavras diferentes. | G25: =IF(F25="Sim",1,IF(F25="Não",0,IF(F25="Às vezes",0.5,"-"))) -> - | H25: 13 Coloca um pino redondo em uma prancha de pinos, quando solicitado. | J25: =IF(I25="Sim",1,IF(I25="Não",0,IF(I25="Às vezes",0.5,"-"))) -> - | K25: 13 Estica braços e pernas ao ser vestido. | M25: =IF(L25="Sim",1,IF(L25="Não",0,IF(L25="Às vezes",0.5,"-"))) -> - | N25: 13 Em DD, vira de barriga para baixo. | P25: =IF(O25="Sim",1,IF(O25="Não",0,IF(O25="Às vezes",0.5,"-"))) -> -
B26: 14 Brinca sozinho por 10 minutos. | D26: =IF(C26="Sim",1,IF(C26="Não",0,IF(C26="Às vezes",0.5,"-"))) -> - | E26: 12 Pede "mais". | G26: =IF(F26="Sim",1,IF(F26="Não",0,IF(F26="Às vezes",0.5,"-"))) -> - | H26: 14 Executa gestos simples quando requisitado. | J26: =IF(I26="Sim",1,IF(I26="Não",0,IF(I26="Às vezes",0.5,"-"))) -> - | K26: Total de Acertos | L26: =SUM(M13:M25) -> 0 | N26: 14 Faz esforço para sentar-se, segurando nos dedos do adulto. | P26: =IF(O26="Sim",1,IF(O26="Não",0,IF(O26="Às vezes",0.5,"-"))) -> -
B27: 15 Procura contato visual quando alguém lhe dá atenção por 2 a 3 minutos. | D27: =IF(C27="Sim",1,IF(C27="Não",0,IF(C27="Às vezes",0.5,"-"))) -> - | E27: 13 Diz "acabou". | G27: =IF(F27="Sim",1,IF(F27="Não",0,IF(F27="Às vezes",0.5,"-"))) -> - | H27: Total de Acertos | I27: =SUM(J13:J26) -> 0 | K27: Auto cuidados – 1 a 2 anos | N27: 15 Vira a cabeça com facilidade quando o corpo está apoiado. | P27: =IF(O27="Sim",1,IF(O27="Não",0,IF(O27="Às vezes",0.5,"-"))) -> -
B28: 16 Brinca sozinho sem reclamar por 15 a 20 minutos, próximo de um adulto. | D28: =IF(C28="Sim",1,IF(C28="Não",0,IF(C28="Às vezes",0.5,"-"))) -> - | E28: 14 Obedece a 3 ordens diferentes que não são acompanhadas de gestos indicativos. | G28: =IF(F28="Sim",1,IF(F28="Não",0,IF(F28="Às vezes",0.5,"-"))) -> - | H28: Cognição – 1 a 2 anos | K28: 14 Come com colher de modo independente. | M28: =IF(L28="Sim",1,IF(L28="Não",0,IF(L28="Às vezes",0.5,"-"))) -> - | N28: 16 Mantém-se sentado por 2 minutos. | P28: =IF(O28="Sim",1,IF(O28="Não",0,IF(O28="Às vezes",0.5,"-"))) -> -
B29: 17 Vocaliza para obter atenção | D29: =IF(C29="Sim",1,IF(C29="Não",0,IF(C29="Às vezes",0.5,"-"))) -> - | E29: 15 Consegue "dar" ou "mostrar" quando solicitado. | G29: =IF(F29="Sim",1,IF(F29="Não",0,IF(F29="Às vezes",0.5,"-"))) -> - | H29: 15 Retira 6 objetos de um recipiente, um por vez. | J29: =IF(I29="Sim",1,IF(I29="Não",0,IF(I29="Às vezes",0.5,"-"))) -> - | K29: 15 Segura a caneca com uma só mão e bebe. | M29: =IF(L29="Sim",1,IF(L29="Não",0,IF(L29="Às vezes",0.5,"-"))) -> - | N29: 17 Solta um objeto para apanhar outro. | P29: =IF(O29="Sim",1,IF(O29="Não",0,IF(O29="Às vezes",0.5,"-"))) -> -
B30: 18 Imita adulto em brincadeiras de esconde-esconde | D30: =IF(C30="Sim",1,IF(C30="Não",0,IF(C30="Às vezes",0.5,"-"))) -> - | E30: 16 Aponta para 12 objetos quando nomeados. | G30: =IF(F30="Sim",1,IF(F30="Não",0,IF(F30="Às vezes",0.5,"-"))) -> - | H30: 16 Aponta para uma parte do corpo. | J30: =IF(I30="Sim",1,IF(I30="Não",0,IF(I30="Às vezes",0.5,"-"))) -> - | K30: 16 Coloca a mão na água e dá tapinhas no rosto com as mãos molhadas, imitando alguém. | M30: =IF(L30="Sim",1,IF(L30="Não",0,IF(L30="Às vezes",0.5,"-"))) -> - | N30: 18 Apanha e deixa cair um objeto propositalmente. | P30: =IF(O30="Sim",1,IF(O30="Não",0,IF(O30="Às vezes",0.5,"-"))) -> -
B31: 19 Bate palmas, imitando um adulto | D31: =IF(C31="Sim",1,IF(C31="Não",0,IF(C31="Às vezes",0.5,"-"))) -> - | E31: 17 Aponta para 3 a 5 figuras em um livro. | G31: =IF(F31="Sim",1,IF(F31="Não",0,IF(F31="Às vezes",0.5,"-"))) -> - | H31: 17 Empilha 3 blocos, dada a ordem. | J31: =IF(I31="Sim",1,IF(I31="Não",0,IF(I31="Às vezes",0.5,"-"))) -> - | K31: 17 Senta-se em um piniquinho ou sanitário infantil por 5 min | M31: =IF(L31="Sim",1,IF(L31="Não",0,IF(L31="Às vezes",0.5,"-"))) -> - | N31: 19 Fica em pé com o máximo de apoio. | P31: =IF(O31="Sim",1,IF(O31="Não",0,IF(O31="Às vezes",0.5,"-"))) -> -
B32: 20 Acena a mão, imitando um adulto. | D32: =IF(C32="Sim",1,IF(C32="Não",0,IF(C32="Às vezes",0.5,"-"))) -> - | E32: 18 Aponta para 3 partes de seu próprio corpo. | G32: =IF(F32="Sim",1,IF(F32="Não",0,IF(F32="Às vezes",0.5,"-"))) -> - | H32: 18 Emparelha objetos semelhantes. | J32: =IF(I32="Sim",1,IF(I32="Não",0,IF(I32="Às vezes",0.5,"-"))) -> - | K32: 18 Coloca um chapéu na cabeça e o remove. | M32: =IF(L32="Sim",1,IF(L32="Não",0,IF(L32="Às vezes",0.5,"-"))) -> - | N32: 20 Estando em pé com apoio, pula para cima e para baixo. | P32: =IF(O32="Sim",1,IF(O32="Não",0,IF(O32="Às vezes",0.5,"-"))) -> -
B33: 21 Ergue os braços para expressar “grande”, imitando um adulto | D33: =IF(C33="Sim",1,IF(C33="Não",0,IF(C33="Às vezes",0.5,"-"))) -> - | E33: 19 Diz seu nome ou apelido quando solicitado. | G33: =IF(F33="Sim",1,IF(F33="Não",0,IF(F33="Às vezes",0.5,"-"))) -> - | H33: 19 Faz rabiscos no papel. | J33: =IF(I33="Sim",1,IF(I33="Não",0,IF(I33="Às vezes",0.5,"-"))) -> - | K33: 19 Tira as meias. | M33: =IF(L33="Sim",1,IF(L33="Não",0,IF(L33="Às vezes",0.5,"-"))) -> - | N33: 21 Engatinha para apanhar um objeto (distante a sua altura). | P33: =IF(O33="Sim",1,IF(O33="Não",0,IF(O33="Às vezes",0.5,"-"))) -> -
B34: 22 Oferece algo, mas nem sempre entrega. | D34: =IF(C34="Sim",1,IF(C34="Não",0,IF(C34="Às vezes",0.5,"-"))) -> - | E34: 20 Responde à pergunta "O que é isto?" | G34: =IF(F34="Sim",1,IF(F34="Não",0,IF(F34="Às vezes",0.5,"-"))) -> - | H34: 20 Aponta para si quando perguntam "Cadê o Fulano?" | J34: =IF(I34="Sim",1,IF(I34="Não",0,IF(I34="Às vezes",0.5,"-"))) -> - | K34: 20 Empurra os braços pelas mangas e os pés pelas pernas da calça. | M34: =IF(L34="Sim",1,IF(L34="Não",0,IF(L34="Às vezes",0.5,"-"))) -> - | N34: 22 Senta-se apoiando-se sozinho. | P34: =IF(O34="Sim",1,IF(O34="Não",0,IF(O34="Às vezes",0.5,"-"))) -> -
B35: 23 Abraça, acaricia e beija familiares. | D35: =IF(C35="Sim",1,IF(C35="Não",0,IF(C35="Às vezes",0.5,"-"))) -> - | E35: 21 Combina palavras e gestos para expressar desejos. | G35: =IF(F35="Sim",1,IF(F35="Não",0,IF(F35="Às vezes",0.5,"-"))) -> - | H35: 21 Coloca 5 pinos redondos, dada a ordem. | J35: =IF(I35="Sim",1,IF(I35="Não",0,IF(I35="Às vezes",0.5,"-"))) -> - | K35: 21 Tira os sapatos quando os cordões estiverem desamarrados | M35: =IF(L35="Sim",1,IF(L35="Não",0,IF(L35="Às vezes",0.5,"-"))) -> - | N35: 23 Estando sentado, vira de gatinhas. | P35: =IF(O35="Sim",1,IF(O35="Não",0,IF(O35="Às vezes",0.5,"-"))) -> -
B36: 24 Responde ao próprio nome, olhando ou estendendo o braço para ser pego. | D36: =IF(C36="Sim",1,IF(C36="Não",0,IF(C36="Às vezes",0.5,"-"))) -> - | E36: 22 Nomeia 5 membros da família, incluindo animais. | G36: =IF(F36="Sim",1,IF(F36="Não",0,IF(F36="Às vezes",0.5,"-"))) -> - | H36: 22 Emparelha objetos com a figura do mesmo nome. | J36: =IF(I36="Sim",1,IF(I36="Não",0,IF(I36="Às vezes",0.5,"-"))) -> - | K36: 22 Tira o casaco quando desabotoado. | M36: =IF(L36="Sim",1,IF(L36="Não",0,IF(L36="Às vezes",0.5,"-"))) -> - | N36: 24 Estando em DV consegue sentar-se. | P36: =IF(O36="Sim",1,IF(O36="Não",0,IF(O36="Às vezes",0.5,"-"))) -> -
B37: 25 Aperta ou sacode um brinquedo para produzir sons, em imitação. | D37: =IF(C37="Sim",1,IF(C37="Não",0,IF(C37="Às vezes",0.5,"-"))) -> - | E37: 23 Nomeia 4 brinquedos. | G37: =IF(F37="Sim",1,IF(F37="Não",0,IF(F37="Às vezes",0.5,"-"))) -> - | H37: 23 Aponta para a figura nomeada. | J37: =IF(I37="Sim",1,IF(I37="Não",0,IF(I37="Às vezes",0.5,"-"))) -> - | K37: 23 Tira a calça quando desabotoada. | M37: =IF(L37="Sim",1,IF(L37="Não",0,IF(L37="Às vezes",0.5,"-"))) -> - | N37: 25 Senta-se sem o apoio das mãos. | P37: =IF(O37="Sim",1,IF(O37="Não",0,IF(O37="Às vezes",0.5,"-"))) -> -
B38: 26 Manipula brinquedo ou objeto. | D38: =IF(C38="Sim",1,IF(C38="Não",0,IF(C38="Às vezes",0.5,"-"))) -> - | E38: 24 Produz sons de animais, ou os nomeia pelo som | G38: =IF(F38="Sim",1,IF(F38="Não",0,IF(F38="Às vezes",0.5,"-"))) -> - | H38: 24 Vira as páginas de um livro (2/3 por vez) para encontrar a figura nomeada. | J38: =IF(I38="Sim",1,IF(I38="Não",0,IF(I38="Às vezes",0.5,"-"))) -> - | K38: 24 Puxa um fecho grande para cima e para baixo. | M38: =IF(L38="Sim",1,IF(L38="Não",0,IF(L38="Às vezes",0.5,"-"))) -> - | N38: 26 Atira objetos ao acaso. | P38: =IF(O38="Sim",1,IF(O38="Não",0,IF(O38="Às vezes",0.5,"-"))) -> -
B39: 27 Estende um brinquedo ou objeto a um adulto e o entrega. | D39: =IF(C39="Sim",1,IF(C39="Não",0,IF(C39="Às vezes",0.5,"-"))) -> - | E39: 25 Pede alimentos conhecidos pelo nome, quando mostrados. | G39: =IF(F39="Sim",1,IF(F39="Não",0,IF(F39="Às vezes",0.5,"-"))) -> - | H39: Total de Acertos | I39: =SUM(J29:J38) -> 0 | K39: 25 Utiliza palavras ou gestos indicando necessidade de ir ao banheiro. | M39: =IF(L39="Sim",1,IF(L39="Não",0,IF(L39="Às vezes",0.5,"-"))) -> - | N39: 27 Balança para frente e para trás quando de gatinhas. | P39: =IF(O39="Sim",1,IF(O39="Não",0,IF(O39="Às vezes",0.5,"-"))) -> -
B40: 28 Imita movimentos de outras crianças ao brincar. | D40: =IF(C40="Sim",1,IF(C40="Não",0,IF(C40="Às vezes",0.5,"-"))) -> - | E40: 26 Faz perguntas variando a entonação da voz | G40: =IF(F40="Sim",1,IF(F40="Não",0,IF(F40="Às vezes",0.5,"-"))) -> - | H40: Cognição – 2 a 3 anos | K40: Total de Acertos | L40: =SUM(M28:M39) -> 0 | N40: 28 Transfere objetos de uma mão para outra quando sentado. | P40: =IF(O40="Sim",1,IF(O40="Não",0,IF(O40="Às vezes",0.5,"-"))) -> -
B41: Total de Acertos | C41: =SUM(D13:D40) -> 0 | E41: 27 Nomeia 3 partes do corpo em uma boneca ou outra pessoa. | G41: =IF(F41="Sim",1,IF(F41="Não",0,IF(F41="Às vezes",0.5,"-"))) -> - | H41: 25 Encontra determinado livro quando solicitado. | J41: =IF(I41="Sim",1,IF(I41="Não",0,IF(I41="Às vezes",0.5,"-"))) -> - | K41: Auto cuidados – 2 a 3 anos | N41: 29 Retém em uma das mãos 2 cubos de 2,5 cm. | P41: =IF(O41="Sim",1,IF(O41="Não",0,IF(O41="Às vezes",0.5,"-"))) -> -
B42: Socialização – 1 a 2 anos | C42: Sim/Não/Às vezes | D42: Ptos | E42: 28 Responde a perguntas de sim / não. | G42: =IF(F42="Sim",1,IF(F42="Não",0,IF(F42="Às vezes",0.5,"-"))) -> - | H42: 26 Completa um quebra-cabeça de encaixe de 3 peças. | J42: =IF(I42="Sim",1,IF(I42="Não",0,IF(I42="Às vezes",0.5,"-"))) -> - | K42: 26 Alimenta-se sozinho usando colher ou caneca, derrubando um pouco de comida ou derramando pouco líquido. | L42: Sim | M42: =IF(L42="Sim",1,IF(L42="Não",0,IF(L42="Às vezes",0.5,"-"))) -> 1 | N42: 30 Fica de joelhos. | P42: =IF(O42="Sim",1,IF(O42="Não",0,IF(O42="Às vezes",0.5,"-"))) -> -
B43: 29 Imita um adulto em uma tarefa simples. | D43: =IF(C43="Sim",1,IF(C43="Não",0,IF(C43="Às vezes",0.5,"-"))) -> - | E43: Total de Acertos | F43: =SUM(G25:G42) -> 0 | H43: 27 Nomeia 4 objetos comuns em figuras. | J43: =IF(I43="Sim",1,IF(I43="Não",0,IF(I43="Às vezes",0.5,"-"))) -> - | K43: 27 Quando recebe uma toalha enxuga as mãos e o rosto com ajuda | L43: Sim | M43: =IF(L43="Sim",1,IF(L43="Não",0,IF(L43="Às vezes",0.5,"-"))) -> 1 | N43: 31 Fica em pé, apoiando-se em algo. | P43: =IF(O43="Sim",1,IF(O43="Não",0,IF(O43="Às vezes",0.5,"-"))) -> -
...

Sheet CÁLCULOS e GRAF AV1
A1: e
B2: GUIA PORTAGE DE EDUCAÇÃO PRÉ-ESCOLAR
B5: IDADE DE DESENVOLVIMENTO DA CRIANÇA | C5: =((E31+K31+E41+K41+E51)/12)/6 -> 0.28649237
B7: IDADE DA CRIANÇA POR ÁREA
B8: =B17 -> SOCIALIZAÇÃO | C8: =E32 -> 0
B9: =B18 -> LINGUAGEM | C9: =K32 -> 0
B10: =B19 -> COGNIÇÃO | C10: =E42 -> 0
B11: =B20 -> AUTOCUIDADOS | C11: =K42 -> 0.77777778
B12: =B21 -> DESENVOLVIMENTO MOTOR | C12: =E52 -> 0.94117647
B14: * As tabelas e gráficos abaixo são automáticos, não sendo necessário o preenchimento
C15: % Acertos por faixa etária
B16: ÁREA DE DESENVOLVIMENTO | C16: 0 - 1 ano | D16: 1 - 2 anos | E16: 2 - 3 anos | F16: 3 - 4 anos | G16: 4 - 5 anos | H16: 5 - 6 anos | I16: % Acertos Total
B17: =B24 -> SOCIALIZAÇÃO | C17: 0 | D17: 0 | E17: =F27 -> 0 | F17: =F28 -> 0 | G17: =F29 -> 0 | H17: =F30 -> 0 | I17: =F31 -> 0
B18: =H24 -> LINGUAGEM | C18: =L25 -> 0 | D18: 0 | E18: 0 | F18: =L28 -> 0 | G18: =L29 -> 0 | H18: =L30 -> 0 | I18: =L31 -> 0
B19: =B34 -> COGNIÇÃO | C19: 0 | D19: 0 | E19: =F37 -> 0 | F19: =F38 -> 0 | G19: =F39 -> 0 | H19: =F40 -> 0 | I19: =F41 -> 0
B20: =H34 -> AUTOCUIDADOS | C20: 0 | D20: 0 | E20: =L37 -> 0.77777778 | F20: =L38 -> 0 | G20: =L39 -> 0 | H20: =L40 -> 0 | I20: =L41 -> 0.2
B21: =B44 -> DESENVOLVIMENTO MOTOR | C21: 0 | D21: 0 | E21: =F47 -> 0.94117647 | F21: =F48 -> 0 | G21: =F49 -> 0 | H21: =F50 -> 0 | I21: =F51 -> 0.11428571
B24: SOCIALIZAÇÃO | C24: Pontuação (Acertos) | D24: Pontuação Esperada | E24: Idade | F24: % Acertos | H24: LINGUAGEM | I24: Pontuação (Acertos) | J24: Pontuação Esperada | K24: Idade | L24: % Acertos
B25: ='AV 1'!B12 -> Socialização - 0 a 1 ano | C25: ='AV 1'!C41 -> 0 | D25: 28 | E25: =(C25*12)/D25 -> 0 | F25: =C25/D25 -> 0 | H25: ='AV 1'!E12 -> Linguagem – 0 a 1 anos | I25: ='AV 1'!F23 -> 0 | J25: 10 | K25: =(I25*12)/J25 -> 0 | L25: =I25/J25 -> 0
B26: ='AV 1'!B42 -> Socialização – 1 a 2 anos | C26: ='AV 1'!C58 -> 0 | D26: 15 | E26: =(C26*12)/D26 -> 0 | F26: =C26/D26 -> 0 | H26: ='AV 1'!E24 -> Linguagem – 1 a 2 anos | I26: ='AV 1'!F43 -> 0 | J26: 18 | K26: =(I26*12)/J26 -> 0 | L26: =I26/J26 -> 0
B27: ='AV 1'!B59 -> Socialização – 2 a 3 anos | C27: ='AV 1'!C68 -> 0 | D27: 8 | E27: =(C27*12)/D27 -> 0 | F27: =C27/D27 -> 0 | H27: ='AV 1'!E44 -> Linguagem – 2 a 3 anos | I27: ='AV 1'!F75 -> 0 | J27: 30 | K27: =(I27*12)/J27 -> 0 | L27: =I27/J27 -> 0
B28: ='AV 1'!B69 -> Socialização – 3 a 4 anos | C28: ='AV 1'!C82 -> 0 | D28: 12 | E28: =(C28*12)/D28 -> 0 | F28: =C28/D28 -> 0 | H28: ='AV 1'!E76 -> Linguagem – 3 a 4 anos | I28: ='AV 1'!F89 -> 0 | J28: 12 | K28: =(I28*12)/J28 -> 0 | L28: =I28/J28 -> 0
B29: ='AV 1'!B83 -> Socialização – 4 a 5 anos | C29: ='AV 1'!C93 -> 0 | D29: 9 | E29: =(C29*12)/D29 -> 0 | F29: =C29/D29 -> 0 | H29: ='AV 1'!E90 -> Linguagem – 4 a 5 anos | I29: ='AV 1'!F106 -> 0 | J29: 15 | K29: =(I29*12)/J29 -> 0 | L29: =I29/J29 -> 0
B30: ='AV 1'!B94 -> Socialização – 5 a 6 anos | C30: ='AV 1'!C106 -> 0 | D30: 11 | E30: =(C30*12)/D30 -> 0 | F30: =C30/D30 -> 0 | H30: ='AV 1'!E107 -> Linguagem – 5 a 6 anos | I30: ='AV 1'!F122 -> 0 | J30: 14 | K30: =(I30*12)/J30 -> 0 | L30: =I30/J30 -> 0
B31: TOTAL | C31: =SUM(C25:C30) -> 0 | D31: =SUM(D25:D30) -> 83 | E31: =SUM(E25:E30) -> 0 | F31: =C31/D31 -> 0 | H31: TOTAL | I31: =SUM(I25:I30) -> 0 | J31: =SUM(J25:J30) -> 99 | K31: =SUM(K25:K30) -> 0 | L31: =I31/J31 -> 0
B32: IDADE DA CRIANÇA - SOCIALIZAÇÃO | E32: =E31/12 -> 0 | H32: IDADE DA CRIANÇA - LINGUAGEM | K32: =K31/12 -> 0
B34: COGNIÇÃO | C34: Pontuação (Acertos) | D34: Pontuação Esperada | E34: Idade | F34: % Acertos | H34: AUTOCUIDADOS | I34: Pontuação (Acertos) | J34: Pontuação Esperada | K34: Idade | L34: % Acertos
B35: ='AV 1'!H12 -> Cognição – 0 a 1 ano | C35: ='AV 1'!I27 -> 0 | D35: 14 | E35: =(C35*12)/D35 -> 0 | F35: =C35/D35 -> 0 | H35: ='AV 1'!K12 -> Auto cuidados – 0 a 1 anos | I35: ='AV 1'!L26 -> 0 | J35: 13 | K35: =(I35*12)/J35 -> 0 | L35: =I35/J35 -> 0
B36: ='AV 1'!H28 -> Cognição – 1 a 2 anos | C36: ='AV 1'!I39 -> 0 | D36: 10 | E36: =(C36*12)/D36 -> 0 | F36: =C36/D36 -> 0 | H36: ='AV 1'!K27 -> Auto cuidados – 1 a 2 anos | I36: ='AV 1'!L40 -> 0 | J36: 12 | K36: =(I36*12)/J36 -> 0 | L36: =I36/J36 -> 0
B37: ='AV 1'!H40 -> Cognição – 2 a 3 anos | C37: ='AV 1'!I57 -> 0 | D37: 16 | E37: =(C37*12)/D37 -> 0 | F37: =C37/D37 -> 0 | H37: ='AV 1'!K41 -> Auto cuidados – 2 a 3 anos | I37: ='AV 1'!L69 -> 21 | J37: 27 | K37: =(I37*12)/J37 -> 9.3333333 | L37: =I37/J37 -> 0.77777778
B38: ='AV 1'!H58 -> Cognição – 3 a 4 anos | C38: ='AV 1'!I83 -> 0 | D38: 24 | E38: =(C38*12)/D38 -> 0 | F38: =C38/D38 -> 0 | H38: ='AV 1'!K70 -> Auto cuidados – 3 a 4 anos | I38: ='AV 1'!L86 -> 0 | J38: 15 | K38: =(I38*12)/J38 -> 0 | L38: =I38/J38 -> 0
B39: ='AV 1'!H84 -> Cognição – 4 a 5 anos | C39: ='AV 1'!I107 -> 0 | D39: 22 | E39: =(C39*12)/D39 -> 0 | F39: =C39/D39 -> 0 | H39: ='AV 1'!K87 -> Auto cuidados – 4 a 5 anos | I39: ='AV 1'!L111 -> 0 | J39: 23 | K39: =(I39*12)/J39 -> 0 | L39: =I39/J39 -> 0
B40: ='AV 1'!H108 -> Cognição – 5 a 6 anos | C40: ='AV 1'!I131 -> 0 | D40: 22 | E40: =(C40*12)/D40 -> 0 | F40: =C40/D40 -> 0 | H40: ='AV 1'!K112 -> Auto cuidados – 5 a 6 anos | I40: ='AV 1'!L128 -> 0 | J40: 15 | K40: =(I40*12)/J40 -> 0 | L40: =I40/J40 -> 0
B41: TOTAL | C41: =SUM(C35:C40) -> 0 | D41: =SUM(D35:D40) -> 108 | E41: =SUM(E35:E40) -> 0 | F41: =C41/D41 -> 0 | H41: TOTAL | I41: =SUM(I35:I40) -> 21 | J41: =SUM(J35:J40) -> 105 | K41: =SUM(K35:K40) -> 9.3333333 | L41: =I41/J41 -> 0.2
B42: IDADE DA CRIANÇA - COGNIÇÃO | E42: =E41/12 -> 0 | H42: IDADE DA CRIANÇA - AUTOCUIDADOS | K42: =K41/12 -> 0.77777778
B44: DESENVOLVIMENTO MOTOR | C44: Pontuação (Acertos) | D44: Pontuação Esperada | E44: Idade | F44: % Acertos
B45: ='AV 1'!N12 -> Desenvolvimento Motor – 0 a 1 ano | C45: ='AV 1'!O58 -> 0 | D45: 45 | E45: =(C45*12)/D45 -> 0 | F45: =C45/D45 -> 0
B46: ='AV 1'!N59 -> Desenvolvimento Motor – 1 a 2 anos | C46: ='AV 1'!O78 -> 0 | D46: 18 | E46: =(C46*12)/D46 -> 0 | F46: =C46/D46 -> 0
B47: ='AV 1'!N79 -> Desenvolvimento Motor – 2 a 3 anos | C47: ='AV 1'!O97 -> 16 | D47: 17 | E47: =(C47*12)/D47 -> 11.294118 | F47: =C47/D47 -> 0.94117647
B48: ='AV 1'!N98 -> Desenvolvimento Motor – 3 a 4 ano | C48: ='AV 1'!O114 -> 0 | D48: 15 | E48: =(C48*12)/D48 -> 0 | F48: =C48/D48 -> 0
...

Sheet PEI AV1
B2: GUIA PORTAGE DE EDUCAÇÃO PRÉ-ESCOLAR
B4: Nome:
B5: Idade: | C5: 6
B6: Avaliador:
B7: Data da Avaliação:
B9: * A tabela abaixo é automática, não sendo necessário o preenchimento. Filtre primeiro Objetivos Prioritários, retire o filtro, e faça novo filtro em Demais Objetivos.
B10: PLANO DE ENSINO INDIVIDUALIZADO
B11: OBJETIVOS PRIORITÁRIOS | C11: DEMAIS OBJETIVOS
B12: SOCIALIZAÇÃO | C12: SOCIALIZAÇÃO
B13: =IF('AV 1'!C13="Às vezes",'AV 1'!B13,"-") -> - | C13: =IF('AV 1'!C13="Não",'AV 1'!B13,"-") -> -
B14: =IF('AV 1'!C14="Às vezes",'AV 1'!B14,"-") -> - | C14: =IF('AV 1'!C14="Não",'AV 1'!B14,"-") -> -
B15: =IF('AV 1'!C15="Às vezes",'AV 1'!B15,"-") -> - | C15: =IF('AV 1'!C15="Não",'AV 1'!B15,"-") -> -
B16: =IF('AV 1'!C16="Às vezes",'AV 1'!B16,"-") -> - | C16: =IF('AV 1'!C16="Não",'AV 1'!B16,"-") -> -
B17: =IF('AV 1'!C17="Às vezes",'AV 1'!B17,"-") -> - | C17: =IF('AV 1'!C17="Não",'AV 1'!B17,"-") -> -
B18: =IF('AV 1'!C18="Às vezes",'AV 1'!B18,"-") -> - | C18: =IF('AV 1'!C18="Não",'AV 1'!B18,"-") -> -
B19: =IF('AV 1'!C19="Às vezes",'AV 1'!B19,"-") -> - | C19: =IF('AV 1'!C19="Não",'AV 1'!B19,"-") -> -
B20: =IF('AV 1'!C20="Às vezes",'AV 1'!B20,"-") -> - | C20: =IF('AV 1'!C20="Não",'AV 1'!B20,"-") -> -
B21: =IF('AV 1'!C21="Às vezes",'AV 1'!B21,"-") -> - | C21: =IF('AV 1'!C21="Não",'AV 1'!B21,"-") -> -
B22: =IF('AV 1'!C22="Às vezes",'AV 1'!B22,"-") -> - | C22: =IF('AV 1'!C22="Não",'AV 1'!B22,"-") -> -
B23: =IF('AV 1'!C23="Às vezes",'AV 1'!B23,"-") -> - | C23: =IF('AV 1'!C23="Não",'AV 1'!B23,"-") -> -
B24: =IF('AV 1'!C24="Às vezes",'AV 1'!B24,"-") -> - | C24: =IF('AV 1'!C24="Não",'AV 1'!B24,"-") -> -
... B105: =IF('AV 1'!C105="Às vezes",'AV 1'!B105,"-") -> - | C105: =IF('AV 1'!C105="Não",'AV 1'!B105,"-") -> -
B106: LINGUAGEM | C106: LINGUAGEM
B107: =IF('AV 1'!F13="Às vezes",'AV 1'!E13,"-") -> - | C107: =IF('AV 1'!F13="Não",'AV 1'!E13,"-") -> -
B108: =IF('AV 1'!F14="Às vezes",'AV 1'!E14,"-") -> - | C108: =IF('AV 1'!F14="Não",'AV 1'!E14,"-") -> -
B109: =IF('AV 1'!F15="Às vezes",'AV 1'!E15,"-") -> - | C109: =IF('AV 1'!F15="Não",'AV 1'!E15,"-") -> -
B110: =IF('AV 1'!F16="Às vezes",'AV 1'!E16,"-") -> - | C110: =IF('AV 1'!F16="Não",'AV 1'!E16,"-") -> -
B111: =IF('AV 1'!F17="Às vezes",'AV 1'!E17,"-") -> - | C111: =IF('AV 1'!F17="Não",'AV 1'!E17,"-") -> -
B112: =IF('AV 1'!F18="Às vezes",'AV 1'!E18,"-") -> - | C112: =IF('AV 1'!F18="Não",'AV 1'!E18,"-") -> -
B113: =IF('AV 1'!F19="Às vezes",'AV 1'!E19,"-") -> - | C113: =IF('AV 1'!F19="Não",'AV 1'!E19,"-") -> -
B114: =IF('AV 1'!F20="Às vezes",'AV 1'!E20,"-") -> - | C114: =IF('AV 1'!F20="Não",'AV 1'!E20,"-") -> -
B115: =IF('AV 1'!F21="Às vezes",'AV 1'!E21,"-") -> - | C115: =IF('AV 1'!F21="Não",'AV 1'!E21,"-") -> -
B116: =IF('AV 1'!F22="Às vezes",'AV 1'!E22,"-") -> - | C116: =IF('AV 1'!F22="Não",'AV 1'!E22,"-") -> -
B117: =IF('AV 1'!F23="Às vezes",'AV 1'!E23,"-") -> - | C117: =IF('AV 1'!F23="Não",'AV 1'!E23,"-") -> -
B118: =IF('AV 1'!F24="Às vezes",'AV 1'!E24,"-") -> - | C118: =IF('AV 1'!F24="Não",'AV 1'!E24,"-") -> -
... B215: =IF('AV 1'!F121="Às vezes",'AV 1'!E121,"-") -> - | C215: =IF('AV 1'!F121="Não",'AV 1'!E121,"-") -> -
B216: COGNIÇÃO | C216: COGNIÇÃO
B217: =IF('AV 1'!I13="Às vezes",'AV 1'!H13,"-") -> - | C217: =IF('AV 1'!I13="Não",'AV 1'!H13,"-") -> -
B218: =IF('AV 1'!I14="Às vezes",'AV 1'!H14,"-") -> - | C218: =IF('AV 1'!I14="Não",'AV 1'!H14,"-") -> -
B219: =IF('AV 1'!I15="Às vezes",'AV 1'!H15,"-") -> - | C219: =IF('AV 1'!I15="Não",'AV 1'!H15,"-") -> -
...

Sheet AV 2
B2: GUIA PORTAGE DE EDUCAÇÃO PRÉ-ESCOLAR
B4: Nome: | C4: JY Silva
B5: Idade: (insira apenas o número) | C5: 6
B6: Avaliador: | C6: Maria Luiza
B7: Data da Avaliação: | C7: 45737
B9: * Nas tabelas abaixo, insira apenas SIM, NÃO e ÀS VEZES QUE CONSTAM NA LISTA DE OPÇÕES DE CADA CÉLULA. Não digite texto algum, apenas selecione a opção da lista. Os totais e pontos são automáticos.
B10: Legendas: Sim (alcançou): 1 pto | N – Não - ainda não alcançou: 0 pto | AV - Às vezes: 0,5 ptos | NA: Não Avaliado | Total de Acertos = Pontuação Total. Não deixe espaços vazios. Se o item não foi avaliado, marque a opção NA.
B11: SOCIALIZAÇÃO | E11: LINGUAGEM | H11: COGNIÇÃO | K11: AUTOCUIDADOS | N11: DESENVOLVIMENTO MOTOR
B12: Socialização - 0 a 1 ano | C12: Sim/Não/Às vezes | D12: Ptos | E12: Linguagem – 0 a 1 anos | F12: Sim/Não/Às vezes | G12: Ptos | H12: Cognição – 0 a 1 ano | I12: Sim/Não/Às vezes | J12: Ptos | K12: Auto cuidados – 0 a 1 anos | L12: Sim/Não/Às vezes | M12: Ptos | N12: Desenvolvimento Motor – 0 a 1 ano | O12: Sim/Não/Às vezes | P12: Ptos
B13: 01 Observa uma pessoa movimentando-se em seu campo visual. | C13: Sim | D13: =IF(C13="Sim",1,IF(C13="Não",0,IF(C13="Às vezes",0.5,"-"))) -> 1 | E13: 01 Repete sons emitidos por outras pessoas. | G13: =IF(F13="Sim",1,IF(F13="Não",0,IF(F13="Às vezes",0.5,"-"))) -> - | H13: 01 Remove um pano do rosto que obscureça sua visão. | J13: =IF(I13="Sim",1,IF(I13="Não",0,IF(I13="Às vezes",0.5,"-"))) -> - | K13: 01 Suga e deglute líquidos. | M13: =IF(L13="Sim",1,IF(L13="Não",0,IF(L13="Às vezes",0.5,"-"))) -> - | N13: 01 Alcança um objeto colocado à sua frente (15 a 20 cm.). | P13: =IF(O13="Sim",1,IF(O13="Não",0,IF(O13="Às vezes",0.5,"-"))) -> -
B14: 02 Sorri em resposta à atenção do adulto | C14: Não | D14: =IF(C14="Sim",1,IF(C14="Não",0,IF(C14="Às vezes",0.5,"-"))) -> 0 | E14: 02 Repete a mesma sílaba 2 a 3 vezes. | G14: =IF(F14="Sim",1,IF(F14="Não",0,IF(F14="Às vezes",0.5,"-"))) -> - | H14: 02 Procura com o olhar um objeto que foi tirado de seu campo visual. | J14: =IF(I14="Sim",1,IF(I14="Não",0,IF(I14="Às vezes",0.5,"-"))) -> - | K14: 02 Toma mingau / sopinha. | M14: =IF(L14="Sim",1,IF(L14="Não",0,IF(L14="Às vezes",0.5,"-"))) -> - | N14: 02 Apanha um objeto colocado à sua frente (8 cm.). | P14: =IF(O14="Sim",1,IF(O14="Não",0,IF(O14="Às vezes",0.5,"-"))) -> -
B15: 03 Vocaliza em resposta à atenção | C15: Às vezes | D15: =IF(C15="Sim",1,IF(C15="Não",0,IF(C15="Às vezes",0.5,"-"))) -> 0.5 | E15: 03 Responde a gestos com gestos. | G15: =IF(F15="Sim",1,IF(F15="Não",0,IF(F15="Às vezes",0.5,"-"))) -> - | H15: 03 Remove um objeto de um recipiente colocando a mão dentro do mesmo | J15: =IF(I15="Sim",1,IF(I15="Não",0,IF(I15="Às vezes",0.5,"-"))) -> - | K15: 03 Estende as mãos em direção a mamadeira, tentando pegá-la | M15: =IF(L15="Sim",1,IF(L15="Não",0,IF(L15="Às vezes",0.5,"-"))) -> - | N15: 03 Estende os braços em direção a um objeto à sua frente e o apanha. | P15: =IF(O15="Sim",1,IF(O15="Não",0,IF(O15="Às vezes",0.5,"-"))) -> -
B16: 04 Olha para sua própria mão, sorrindo ou vocalizando | C16: NA | D16: =IF(C16="Sim",1,IF(C16="Não",0,IF(C16="Às vezes",0.5,"-"))) -> - | E16: 04 Obedece a uma ordem simples, quando acompanhada de gestos indicativos. | G16: =IF(F16="Sim",1,IF(F16="Não",0,IF(F16="Às vezes",0.5,"-"))) -> - | H16: 04 Coloca um objeto em um recipiente imitando um adulto. | J16: =IF(I16="Sim",1,IF(I16="Não",0,IF(I16="Às vezes",0.5,"-"))) -> - | K16: 04 Come alimentos liquidificados dados pelos pais. | M16: =IF(L16="Sim",1,IF(L16="Não",0,IF(L16="Às vezes",0.5,"-"))) -> - | N16: 04 Alcança um objeto preferido. | P16: =IF(O16="Sim",1,IF(O16="Não",0,IF(O16="Às vezes",0.5,"-"))) -> -
B17: 05 Responde a seu círculo familiar, sorrindo, vocalizando ou parando de chorar | D17: =IF(C17="Sim",1,IF(C17="Não",0,IF(C17="Às vezes",0.5,"-"))) -> - | E17: 05 Interrompe a atividade quando lhe dizem "Não" 75% das vezes. | G17: =IF(F17="Sim",1,IF(F17="Não",0,IF(F17="Às vezes",0.5,"-"))) -> - | H17: 05 Coloca um objeto em um recipiente quando recebe instruções. | J17: =IF(I17="Sim",1,IF(I17="Não",0,IF(I17="Às vezes",0.5,"-"))) -> - | K17: 05 Segura a mamadeira sem ajuda enquanto bebe. | M17: =IF(L17="Sim",1,IF(L17="Não",0,IF(L17="Às vezes",0.5,"-"))) -> - | N17: 05 Coloca objetos na boca. | P17: =IF(O17="Sim",1,IF(O17="Não",0,IF(O17="Às vezes",0.5,"-"))) -> -
B18: 06 Sorri em resposta à expressão facial dos outros. | D18: =IF(C18="Sim",1,IF(C18="Não",0,IF(C18="Às vezes",0.5,"-"))) -> - | E18: 06 Responde a perguntas simples com respostas não verbais. | G18: =IF(F18="Sim",1,IF(F18="Não",0,IF(F18="Às vezes",0.5,"-"))) -> - | H18: 06 Balança um brinquedo que produz som, pendurado em um barbante. | J18: =IF(I18="Sim",1,IF(I18="Não",0,IF(I18="Às vezes",0.5,"-"))) -> - | K18: 06 Leva a mamadeira até a boca ou a recusa, empurrando-a | M18: =IF(L18="Sim",1,IF(L18="Não",0,IF(L18="Às vezes",0.5,"-"))) -> - | N18: 06 Eleva a cabeça e o tronco apoiando-se nos braços, ao estar deitado de barriga para baixo. | P18: =IF(O18="Sim",1,IF(O18="Não",0,IF(O18="Às vezes",0.5,"-"))) -> -
B19: 07 Sorri e vocaliza ao ver sua imagem no espelho | D19: =IF(C19="Sim",1,IF(C19="Não",0,IF(C19="Às vezes",0.5,"-"))) -> - | E19: 07 Combina 2 sílabas diferentes quando tenta verbalizar. | G19: =IF(F19="Sim",1,IF(F19="Não",0,IF(F19="Às vezes",0.5,"-"))) -> - | H19: 07 Coloca três objetos em um recipiente e o esvazia. | J19: =IF(I19="Sim",1,IF(I19="Não",0,IF(I19="Às vezes",0.5,"-"))) -> - | K19: 07 Come alimentos amassados dados pelos pais. | M19: =IF(L19="Sim",1,IF(L19="Não",0,IF(L19="Às vezes",0.5,"-"))) -> - | N19: 07 Levanta a cabeça e o tronco apoiando-se em um só braço. | P19: =IF(O19="Sim",1,IF(O19="Não",0,IF(O19="Às vezes",0.5,"-"))) -> -
B20: 08 Acaricia ou toca no rosto de adultos (puxa cabelo, nariz, óculos, etc.). | D20: =IF(C20="Sim",1,IF(C20="Não",0,IF(C20="Às vezes",0.5,"-"))) -> - | E20: 08 Imita padrões de entonação da voz de outras pessoas. | G20: =IF(F20="Sim",1,IF(F20="Não",0,IF(F20="Às vezes",0.5,"-"))) -> - | H20: 08 Transfere um objeto de uma mão à outra para apanhar outro objeto. | J20: =IF(I20="Sim",1,IF(I20="Não",0,IF(I20="Às vezes",0.5,"-"))) -> - | K20: 08 Bebe em uma caneca, segurada pelos pais. | M20: =IF(L20="Sim",1,IF(L20="Não",0,IF(L20="Às vezes",0.5,"-"))) -> - | N20: 08 Toca e explora objetos com a boca. | P20: =IF(O20="Sim",1,IF(O20="Não",0,IF(O20="Às vezes",0.5,"-"))) -> -
B21: 09 Estende a mão em direção a um objeto oferecido. | D21: =IF(C21="Sim",1,IF(C21="Não",0,IF(C21="Às vezes",0.5,"-"))) -> - | E21: 09 Usa uma palavra funcionalmente para indicar objetos ou pessoas. | G21: =IF(F21="Sim",1,IF(F21="Não",0,IF(F21="Às vezes",0.5,"-"))) -> - | H21: 09 Deixa cair e apanha um brinquedo. | J21: =IF(I21="Sim",1,IF(I21="Não",0,IF(I21="Às vezes",0.5,"-"))) -> - | K21: 09 Come alimentos semissólidos dados pelos pais. | M21: =IF(L21="Sim",1,IF(L21="Não",0,IF(L21="Às vezes",0.5,"-"))) -> - | N21: 09 Em DV (decúbito ventral, de bruços), vira de lado e mantém esta posição ½ das vezes. | P21: =IF(O21="Sim",1,IF(O21="Não",0,IF(O21="Às vezes",0.5,"-"))) -> -
B22: 10 Estende os braços em direção a pessoas familiares | D22: =IF(C22="Sim",1,IF(C22="Não",0,IF(C22="Às vezes",0.5,"-"))) -> - | E22: 10 Vocaliza em resposta à fala de outras pessoas. | G22: =IF(F22="Sim",1,IF(F22="Não",0,IF(F22="Às vezes",0.5,"-"))) -> - | H22: 10 Descobre um objeto escondido sob um recipiente. | J22: =IF(I22="Sim",1,IF(I22="Não",0,IF(I22="Às vezes",0.5,"-"))) -> - | K22: 10 Alimenta-se sozinho usando os dedos. | M22: =IF(L22="Sim",1,IF(L22="Não",0,IF(L22="Às vezes",0.5,"-"))) -> - | N22: 10 Em DV, vira de costas. | P22: =IF(O22="Sim",1,IF(O22="Não",0,IF(O22="Às vezes",0.5,"-"))) -> -
B23: 11 Estende a mão e toca sua imagem refletida no espelho. | D23: =IF(C23="Sim",1,IF(C23="Não",0,IF(C23="Às vezes",0.5,"-"))) -> - | E23: Total de Acertos | F23: =SUM(G13:G22) -> 0 | H23: 11 Empurra 3 blocos como se fosse um comboio. | J23: =IF(I23="Sim",1,IF(I23="Não",0,IF(I23="Às vezes",0.5,"-"))) -> - | K23: 11 Segura a caneca com ambas as mãos e bebe. | M23: =IF(L23="Sim",1,IF(L23="Não",0,IF(L23="Às vezes",0.5,"-"))) -> - | N23: 11 Em DV, move-se para frente o equivalente à sua altura. | P23: =IF(O23="Sim",1,IF(O23="Não",0,IF(O23="Às vezes",0.5,"-"))) -> -
B24: 12 Segura e examina por 1 minuto um objeto que lhe foi dado. | D24: =IF(C24="Sim",1,IF(C24="Não",0,IF(C24="Às vezes",0.5,"-"))) -> - | E24: Linguagem – 1 a 2 anos | H24: 12 Remove um círculo de uma prancha, por imitação. | J24: =IF(I24="Sim",1,IF(I24="Não",0,IF(I24="Às vezes",0.5,"-"))) -> - | K24: 12 Leva a colher cheia de comida até a boca com ajuda. | M24: =IF(L24="Sim",1,IF(L24="Não",0,IF(L24="Às vezes",0.5,"-"))) -> - | N24: 12 Em DD (decúbito dorsal), rola para o lado. | P24: =IF(O24="Sim",1,IF(O24="Não",0,IF(O24="Às vezes",0.5,"-"))) -> -
B25: 13 Sacode ou aperta um objeto colocado em sua mão, produzindo sons involuntários. | D25: =IF(C25="Sim",1,IF(C25="Não",0,IF(C25="Às vezes",0.5,"-"))) -> - | E25: 11 Diz 5 palavras diferentes. | G25: =IF(F25="Sim",1,IF(F25="Não",0,IF(F25="Às vezes",0.5,"-"))) -> - | H25: 13 Coloca um pino redondo em uma prancha de pinos, quando solicitado. | J25: =IF(I25="Sim",1,IF(I25="Não",0,IF(I25="Às vezes",0.5,"-"))) -> - | K25: 13 Estica braços e pernas ao ser vestido. | M25: =IF(L25="Sim",1,IF(L25="Não",0,IF(L25="Às vezes",0.5,"-"))) -> - | N25: 13 Em DD, vira de barriga para baixo. | P25: =IF(O25="Sim",1,IF(O25="Não",0,IF(O25="Às vezes",0.5,"-"))) -> -
B26: 14 Brinca sozinho por 10 minutos. | D26: =IF(C26="Sim",1,IF(C26="Não",0,IF(C26="Às vezes",0.5,"-"))) -> - | E26: 12 Pede "mais". | G26: =IF(F26="Sim",1,IF(F26="Não",0,IF(F26="Às vezes",0.5,"-"))) -> - | H26: 14 Executa gestos simples quando requisitado. | J26: =IF(I26="Sim",1,IF(I26="Não",0,IF(I26="Às vezes",0.5,"-"))) -> - | K26: Total de Acertos | L26: =SUM(M13:M25) -> 0 | N26: 14 Faz esforço para sentar-se, segurando nos dedos do adulto. | P26: =IF(O26="Sim",1,IF(O26="Não",0,IF(O26="Às vezes",0.5,"-"))) -> -
B27: 15 Procura contato visual quando alguém lhe dá atenção por 2 a 3 minutos. | D27: =IF(C27="Sim",1,IF(C27="Não",0,IF(C27="Às vezes",0.5,"-"))) -> - | E27: 13 Diz "acabou". | G27: =IF(F27="Sim",1,IF(F27="Não",0,IF(F27="Às vezes",0.5,"-"))) -> - | H27: Total de Acertos | I27: =SUM(J13:J26) -> 0 | K27: Auto cuidados – 1 a 2 anos | N27: 15 Vira a cabeça com facilidade quando o corpo está apoiado. | P27: =IF(O27="Sim",1,IF(O27="Não",0,IF(O27="Às vezes",0.5,"-"))) -> -
B28: 16 Brinca sozinho sem reclamar por 15 a 20 minutos, próximo de um adulto. | D28: =IF(C28="Sim",1,IF(C28="Não",0,IF(C28="Às vezes",0.5,"-"))) -> - | E28: 14 Obedece a 3 ordens diferentes que não são acompanhadas de gestos indicativos. | G28: =IF(F28="Sim",1,IF(F28="Não",0,IF(F28="Às vezes",0.5,"-"))) -> - | H28: Cognição – 1 a 2 anos | K28: 14 Come com colher de modo independente. | M28: =IF(L28="Sim",1,IF(L28="Não",0,IF(L28="Às vezes",0.5,"-"))) -> - | N28: 16 Mantém-se sentado por 2 minutos. | P28: =IF(O28="Sim",1,IF(O28="Não",0,IF(O28="Às vezes",0.5,"-"))) -> -
B29: 17 Vocaliza para obter atenção | D29: =IF(C29="Sim",1,IF(C29="Não",0,IF(C29="Às vezes",0.5,"-"))) -> - | E29: 15 Consegue "dar" ou "mostrar" quando solicitado. | G29: =IF(F29="Sim",1,IF(F29="Não",0,IF(F29="Às vezes",0.5,"-"))) -> - | H29: 15 Retira 6 objetos de um recipiente, um por vez. | J29: =IF(I29="Sim",1,IF(I29="Não",0,IF(I29="Às vezes",0.5,"-"))) -> - | K29: 15 Segura a caneca com uma só mão e bebe. | M29: =IF(L29="Sim",1,IF(L29="Não",0,IF(L29="Às vezes",0.5,"-"))) -> - | N29: 17 Solta um objeto para apanhar outro. | P29: =IF(O29="Sim",1,IF(O29="Não",0,IF(O29="Às vezes",0.5,"-"))) -> -
B30: 18 Imita adulto em brincadeiras de esconde-esconde | D30: =IF(C30="Sim",1,IF(C30="Não",0,IF(C30="Às vezes",0.5,"-"))) -> - | E30: 16 Aponta para 12 objetos quando nomeados. | G30: =IF(F30="Sim",1,IF(F30="Não",0,IF(F30="Às vezes",0.5,"-"))) -> - | H30: 16 Aponta para uma parte do corpo. | J30: =IF(I30="Sim",1,IF(I30="Não",0,IF(I30="Às vezes",0.5,"-"))) -> - | K30: 16 Coloca a mão na água e dá tapinhas no rosto com as mãos molhadas, imitando alguém. | M30: =IF(L30="Sim",1,IF(L30="Não",0,IF(L30="Às vezes",0.5,"-"))) -> - | N30: 18 Apanha e deixa cair um objeto propositalmente. | P30: =IF(O30="Sim",1,IF(O30="Não",0,IF(O30="Às vezes",0.5,"-"))) -> -
B31: 19 Bate palmas, imitando um adulto | D31: =IF(C31="Sim",1,IF(C31="Não",0,IF(C31="Às vezes",0.5,"-"))) -> - | E31: 17 Aponta para 3 a 5 figuras em um livro. | G31: =IF(F31="Sim",1,IF(F31="Não",0,IF(F31="Às vezes",0.5,"-"))) -> - | H31: 17 Empilha 3 blocos, dada a ordem. | J31: =IF(I31="Sim",1,IF(I31="Não",0,IF(I31="Às vezes",0.5,"-"))) -> - | K31: 17 Senta-se em um piniquinho ou sanitário infantil por 5 min | M31: =IF(L31="Sim",1,IF(L31="Não",0,IF(L31="Às vezes",0.5,"-"))) -> - | N31: 19 Fica em pé com o máximo de apoio. | P31: =IF(O31="Sim",1,IF(O31="Não",0,IF(O31="Às vezes",0.5,"-"))) -> -
B32: 20 Acena a mão, imitando um adulto. | D32: =IF(C32="Sim",1,IF(C32="Não",0,IF(C32="Às vezes",0.5,"-"))) -> - | E32: 18 Aponta para 3 partes de seu próprio corpo. | G32: =IF(F32="Sim",1,IF(F32="Não",0,IF(F32="Às vezes",0.5,"-"))) -> - | H32: 18 Emparelha objetos semelhantes. | J32: =IF(I32="Sim",1,IF(I32="Não",0,IF(I32="Às vezes",0.5,"-"))) -> - | K32: 18 Coloca um chapéu na cabeça e o remove. | M32: =IF(L32="Sim",1,IF(L32="Não",0,IF(L32="Às vezes",0.5,"-"))) -> - | N32: 20 Estando em pé com apoio, pula para cima e para baixo. | P32: =IF(O32="Sim",1,IF(O32="Não",0,IF(O32="Às vezes",0.5,"-"))) -> -
B33: 21 Ergue os braços para expressar “grande”, imitando um adulto | D33: =IF(C33="Sim",1,IF(C33="Não",0,IF(C33="Às vezes",0.5,"-"))) -> - | E33: 19 Diz seu nome ou apelido quando solicitado. | G33: =IF(F33="Sim",1,IF(F33="Não",0,IF(F33="Às vezes",0.5,"-"))) -> - | H33: 19 Faz rabiscos no papel. | J33: =IF(I33="Sim",1,IF(I33="Não",0,IF(I33="Às vezes",0.5,"-"))) -> - | K33: 19 Tira as meias. | M33: =IF(L33="Sim",1,IF(L33="Não",0,IF(L33="Às vezes",0.5,"-"))) -> - | N33: 21 Engatinha para apanhar um objeto (distante a sua altura). | P33: =IF(O33="Sim",1,IF(O33="Não",0,IF(O33="Às vezes",0.5,"-"))) -> -
B34: 22 Oferece algo, mas nem sempre entrega. | D34: =IF(C34="Sim",1,IF(C34="Não",0,IF(C34="Às vezes",0.5,"-"))) -> - | E34: 20 Responde à pergunta "O que é isto?" | G34: =IF(F34="Sim",1,IF(F34="Não",0,IF(F34="Às vezes",0.5,"-"))) -> - | H34: 20 Aponta para si quando perguntam "Cadê o Fulano?" | J34: =IF(I34="Sim",1,IF(I34="Não",0,IF(I34="Às vezes",0.5,"-"))) -> - | K34: 20 Empurra os braços pelas mangas e os pés pelas pernas da calça. | M34: =IF(L34="Sim",1,IF(L34="Não",0,IF(L34="Às vezes",0.5,"-"))) -> - | N34: 22 Senta-se apoiando-se sozinho. | P34: =IF(O34="Sim",1,IF(O34="Não",0,IF(O34="Às vezes",0.5,"-"))) -> -
B35: 23 Abraça, acaricia e beija familiares. | D35: =IF(C35="Sim",1,IF(C35="Não",0,IF(C35="Às vezes",0.5,"-"))) -> - | E35: 21 Combina palavras e gestos para expressar desejos. | G35: =IF(F35="Sim",1,IF(F35="Não",0,IF(F35="Às vezes",0.5,"-"))) -> - | H35: 21 Coloca 5 pinos redondos, dada a ordem. | J35: =IF(I35="Sim",1,IF(I35="Não",0,IF(I35="Às vezes",0.5,"-"))) -> - | K35: 21 Tira os sapatos quando os cordões estiverem desamarrados | M35: =IF(L35="Sim",1,IF(L35="Não",0,IF(L35="Às vezes",0.5,"-"))) -> - | N35: 23 Estando sentado, vira de gatinhas. | P35: =IF(O35="Sim",1,IF(O35="Não",0,IF(O35="Às vezes",0.5,"-"))) -> -
B36: 24 Responde ao próprio nome, olhando ou estendendo o braço para ser pego. | D36: =IF(C36="Sim",1,IF(C36="Não",0,IF(C36="Às vezes",0.5,"-"))) -> - | E36: 22 Nomeia 5 membros da família, incluindo animais. | G36: =IF(F36="Sim",1,IF(F36="Não",0,IF(F36="Às vezes",0.5,"-"))) -> - | H36: 22 Emparelha objetos com a figura do mesmo nome. | J36: =IF(I36="Sim",1,IF(I36="Não",0,IF(I36="Às vezes",0.5,"-"))) -> - | K36: 22 Tira o casaco quando desabotoado. | M36: =IF(L36="Sim",1,IF(L36="Não",0,IF(L36="Às vezes",0.5,"-"))) -> - | N36: 24 Estando em DV consegue sentar-se. | P36: =IF(O36="Sim",1,IF(O36="Não",0,IF(O36="Às vezes",0.5,"-"))) -> -
B37: 25 Aperta ou sacode um brinquedo para produzir sons, em imitação. | D37: =IF(C37="Sim",1,IF(C37="Não",0,IF(C37="Às vezes",0.5,"-"))) -> - | E37: 23 Nomeia 4 brinquedos. | G37: =IF(F37="Sim",1,IF(F37="Não",0,IF(F37="Às vezes",0.5,"-"))) -> - | H37: 23 Aponta para a figura nomeada. | J37: =IF(I37="Sim",1,IF(I37="Não",0,IF(I37="Às vezes",0.5,"-"))) -> - | K37: 23 Tira a calça quando desabotoada. | M37: =IF(L37="Sim",1,IF(L37="Não",0,IF(L37="Às vezes",0.5,"-"))) -> - | N37: 25 Senta-se sem o apoio das mãos. | P37: =IF(O37="Sim",1,IF(O37="Não",0,IF(O37="Às vezes",0.5,"-"))) -> -
B38: 26 Manipula brinquedo ou objeto. | D38: =IF(C38="Sim",1,IF(C38="Não",0,IF(C38="Às vezes",0.5,"-"))) -> - | E38: 24 Produz sons de animais, ou os nomeia pelo som | G38: =IF(F38="Sim",1,IF(F38="Não",0,IF(F38="Às vezes",0.5,"-"))) -> - | H38: 24 Vira as páginas de um livro (2/3 por vez) para encontrar a figura nomeada. | J38: =IF(I38="Sim",1,IF(I38="Não",0,IF(I38="Às vezes",0.5,"-"))) -> - | K38: 24 Puxa um fecho grande para cima e para baixo. | M38: =IF(L38="Sim",1,IF(L38="Não",0,IF(L38="Às vezes",0.5,"-"))) -> - | N38: 26 Atira objetos ao acaso. | P38: =IF(O38="Sim",1,IF(O38="Não",0,IF(O38="Às vezes",0.5,"-"))) -> -
B39: 27 Estende um brinquedo ou objeto a um adulto e o entrega. | D39: =IF(C39="Sim",1,IF(C39="Não",0,IF(C39="Às vezes",0.5,"-"))) -> - | E39: 25 Pede alimentos conhecidos pelo nome, quando mostrados. | G39: =IF(F39="Sim",1,IF(F39="Não",0,IF(F39="Às vezes",0.5,"-"))) -> - | H39: Total de Acertos | I39: =SUM(J29:J38) -> 0 | K39: 25 Utiliza palavras ou gestos indicando necessidade de ir ao banheiro. | M39: =IF(L39="Sim",1,IF(L39="Não",0,IF(L39="Às vezes",0.5,"-"))) -> - | N39: 27 Balança para frente e para trás quando de gatinhas. | P39: =IF(O39="Sim",1,IF(O39="Não",0,IF(O39="Às vezes",0.5,"-"))) -> -
B40: 28 Imita movimentos de outras crianças ao brincar. | D40: =IF(C40="Sim",1,IF(C40="Não",0,IF(C40="Às vezes",0.5,"-"))) -> - | E40: 26 Faz perguntas variando a entonação da voz | G40: =IF(F40="Sim",1,IF(F40="Não",0,IF(F40="Às vezes",0.5,"-"))) -> - | H40: Cognição – 2 a 3 anos | K40: Total de Acertos | L40: =SUM(M28:M39) -> 0 | N40: 28 Transfere objetos de uma mão para outra quando sentado. | P40: =IF(O40="Sim",1,IF(O40="Não",0,IF(O40="Às vezes",0.5,"-"))) -> -
B41: Total de Acertos | C41: =SUM(D13:D40) -> 1.5 | E41: 27 Nomeia 3 partes do corpo em uma boneca ou outra pessoa. | G41: =IF(F41="Sim",1,IF(F41="Não",0,IF(F41="Às vezes",0.5,"-"))) -> - | H41: 25 Encontra determinado livro quando solicitado. | J41: =IF(I41="Sim",1,IF(I41="Não",0,IF(I41="Às vezes",0.5,"-"))) -> - | K41: Auto cuidados – 2 a 3 anos | N41: 29 Retém em uma das mãos 2 cubos de 2,5 cm. | P41: =IF(O41="Sim",1,IF(O41="Não",0,IF(O41="Às vezes",0.5,"-"))) -> -
B42: Socialização – 1 a 2 anos | C42: Sim/Não/Às vezes | D42: Ptos | E42: 28 Responde a perguntas de sim / não. | G42: =IF(F42="Sim",1,IF(F42="Não",0,IF(F42="Às vezes",0.5,"-"))) -> - | H42: 26 Completa um quebra-cabeça de encaixe de 3 peças. | J42: =IF(I42="Sim",1,IF(I42="Não",0,IF(I42="Às vezes",0.5,"-"))) -> - | K42: 26 Alimenta-se sozinho usando colher ou caneca, derrubando um pouco de comida ou derramando pouco líquido. | M42: =IF(L42="Sim",1,IF(L42="Não",0,IF(L42="Às vezes",0.5,"-"))) -> - | N42: 30 Fica de joelhos. | P42: =IF(O42="Sim",1,IF(O42="Não",0,IF(O42="Às vezes",0.5,"-"))) -> -
B43: 29 Imita um adulto em uma tarefa simples. | D43: =IF(C43="Sim",1,IF(C43="Não",0,IF(C43="Às vezes",0.5,"-"))) -> - | E43: Total de Acertos | F43: =SUM(G25:G42) -> 0 | H43: 27 Nomeia 4 objetos comuns em figuras. | J43: =IF(I43="Sim",1,IF(I43="Não",0,IF(I43="Às vezes",0.5,"-"))) -> - | K43: 27 Quando recebe uma toalha enxuga as mãos e o rosto com ajuda | M43: =IF(L43="Sim",1,IF(L43="Não",0,IF(L43="Às vezes",0.5,"-"))) -> - | N43: 31 Fica em pé, apoiando-se em algo. | P43: =IF(O43="Sim",1,IF(O43="Não",0,IF(O43="Às vezes",0.5,"-"))) -> -
...

Sheet CÁLCULOS E GRAF AV2
B2: GUIA PORTAGE DE EDUCAÇÃO PRÉ-ESCOLAR
B5: IDADE DE DESENVOLVIMENTO DA CRIANÇA | C5: =((E31+K31+E41+K41+E51)/12)/6 -> 0.0089285714
B7: IDADE DA CRIANÇA POR ÁREA
B8: =B17 -> SOCIALIZAÇÃO | C8: =E32 -> 0.053571429
B9: =B18 -> LINGUAGEM | C9: =K32 -> 0
B10: =B19 -> COGNIÇÃO | C10: =E42 -> 0
B11: =B20 -> AUTOCUIDADOS | C11: =K42 -> 0
B12: =B21 -> DESENVOLVIMENTO MOTOR | C12: =E52 -> 0
B14: * As tabelas e gráficos abaixo são automáticos, não sendo necessário o preenchimento
C15: % Acertos por faixa etária
B16: ÁREA DE DESENVOLVIMENTO | C16: 0 - 1 ano | D16: 1 - 2 anos | E16: 2 - 3 anos | F16: 3 - 4 anos | G16: 4 - 5 anos | H16: 5 - 6 anos | I16: % Acertos Total
B17: =B24 -> SOCIALIZAÇÃO | C17: =F25 -> 0.053571429 | D17: =F26 -> 0 | E17: =F27 -> 0 | F17: =F28 -> 0 | G17: =F29 -> 0 | H17: =F30 -> 0 | I17: =F31 -> 0.018072289
B18: =H24 -> LINGUAGEM | C18: =L25 -> 0 | D18: =L26 -> 0 | E18: =L27 -> 0 | F18: =L28 -> 0 | G18: =L29 -> 0 | H18: =L30 -> 0 | I18: =L31 -> 0
B19: =B34 -> COGNIÇÃO | C19: =F35 -> 0 | D19: =F36 -> 0 | E19: =F37 -> 0 | F19: =F38 -> 0 | G19: =F39 -> 0 | H19: =F40 -> 0 | I19: =F41 -> 0
B20: =H34 -> AUTOCUIDADOS | C20: =L35 -> 0 | D20: =L36 -> 0 | E20: =L37 -> 0 | F20: =L38 -> 0 | G20: =L39 -> 0 | H20: =L40 -> 0 | I20: =L41 -> 0
B21: =B44 -> DESENVOLVIMENTO MOTOR | C21: =F45 -> 0 | D21: =F46 -> 0 | E21: =F47 -> 0 | F21: =F48 -> 0 | G21: =F49 -> 0 | H21: =F50 -> 0 | I21: =F51 -> 0
B24: SOCIALIZAÇÃO | C24: Pontuação (Acertos) | D24: Pontuação Esperada | E24: Idade | F24: % Acertos | H24: LINGUAGEM | I24: Pontuação (Acertos) | J24: Pontuação Esperada | K24: Idade | L24: % Acertos
B25: ='AV 1'!B12 -> Socialização - 0 a 1 ano | C25: ='AV 2'!C41 -> 1.5 | D25: 28 | E25: =(C25*12)/D25 -> 0.64285714 | F25: =C25/D25 -> 0.053571429 | H25: ='AV 1'!E12 -> Linguagem – 0 a 1 anos | I25: ='AV 2'!F23 -> 0 | J25: 10 | K25: =(I25*12)/J25 -> 0 | L25: =I25/J25 -> 0
B26: ='AV 1'!B42 -> Socialização – 1 a 2 anos | C26: ='AV 2'!C58 -> 0 | D26: 15 | E26: =(C26*12)/D26 -> 0 | F26: =C26/D26 -> 0 | H26: ='AV 1'!E24 -> Linguagem – 1 a 2 anos | I26: ='AV 2'!F43 -> 0 | J26: 18 | K26: =(I26*12)/J26 -> 0 | L26: =I26/J26 -> 0
B27: ='AV 1'!B59 -> Socialização – 2 a 3 anos | C27: ='AV 2'!C68 -> 0 | D27: 8 | E27: =(C27*12)/D27 -> 0 | F27: =C27/D27 -> 0 | H27: ='AV 1'!E44 -> Linguagem – 2 a 3 anos | I27: ='AV 2'!F75 -> 0 | J27: 30 | K27: =(I27*12)/J27 -> 0 | L27: =I27/J27 -> 0
B28: ='AV 1'!B69 -> Socialização – 3 a 4 anos | C28: ='AV 2'!C82 -> 0 | D28: 12 | E28: =(C28*12)/D28 -> 0 | F28: =C28/D28 -> 0 | H28: ='AV 1'!E76 -> Linguagem – 3 a 4 anos | I28: ='AV 2'!F89 -> 0 | J28: 12 | K28: =(I28*12)/J28 -> 0 | L28: =I28/J28 -> 0
B29: ='AV 1'!B83 -> Socialização – 4 a 5 anos | C29: ='AV 2'!C93 -> 0 | D29: 9 | E29: =(C29*12)/D29 -> 0 | F29: =C29/D29 -> 0 | H29: ='AV 1'!E90 -> Linguagem – 4 a 5 anos | I29: ='AV 2'!F106 -> 0 | J29: 15 | K29: =(I29*12)/J29 -> 0 | L29: =I29/J29 -> 0
B30: ='AV 1'!B94 -> Socialização – 5 a 6 anos | C30: ='AV 2'!C106 -> 0 | D30: 11 | E30: =(C30*12)/D30 -> 0 | F30: =C30/D30 -> 0 | H30: ='AV 1'!E107 -> Linguagem – 5 a 6 anos | I30: ='AV 2'!F122 -> 0 | J30: 14 | K30: =(I30*12)/J30 -> 0 | L30: =I30/J30 -> 0
B31: TOTAL | C31: =SUM(C25:C30) -> 1.5 | D31: =SUM(D25:D30) -> 83 | E31: =SUM(E25:E30) -> 0.64285714 | F31: =C31/D31 -> 0.018072289 | H31: TOTAL | I31: =SUM(I25:I30) -> 0 | J31: =SUM(J25:J30) -> 99 | K31: =SUM(K25:K30) -> 0 | L31: =I31/J31 -> 0
B32: IDADE DA CRIANÇA - SOCIALIZAÇÃO | E32: =E31/12 -> 0.053571429 | H32: IDADE DA CRIANÇA - LINGUAGEM | K32: =K31/12 -> 0
B34: COGNIÇÃO | C34: Pontuação (Acertos) | D34: Pontuação Esperada | E34: Idade | F34: % Acertos | H34: AUTOCUIDADOS | I34: Pontuação (Acertos) | J34: Pontuação Esperada | K34: Idade | L34: % Acertos
B35: ='AV 1'!H12 -> Cognição – 0 a 1 ano | C35: ='AV 2'!I27 -> 0 | D35: 14 | E35: =(C35*12)/D35 -> 0 | F35: =C35/D35 -> 0 | H35: ='AV 1'!K12 -> Auto cuidados – 0 a 1 anos | I35: ='AV 2'!L26 -> 0 | J35: 13 | K35: =(I35*12)/J35 -> 0 | L35: =I35/J35 -> 0
B36: ='AV 1'!H28 -> Cognição – 1 a 2 anos | C36: ='AV 2'!I39 -> 0 | D36: 10 | E36: =(C36*12)/D36 -> 0 | F36: =C36/D36 -> 0 | H36: ='AV 1'!K27 -> Auto cuidados – 1 a 2 anos | I36: ='AV 2'!L40 -> 0 | J36: 12 | K36: =(I36*12)/J36 -> 0 | L36: =I36/J36 -> 0
B37: ='AV 1'!H40 -> Cognição – 2 a 3 anos | C37: ='AV 2'!I57 -> 0 | D37: 16 | E37: =(C37*12)/D37 -> 0 | F37: =C37/D37 -> 0 | H37: ='AV 1'!K41 -> Auto cuidados – 2 a 3 anos | I37: ='AV 2'!L69 -> 0 | J37: 27 | K37: =(I37*12)/J37 -> 0 | L37: =I37/J37 -> 0
B38: ='AV 1'!H58 -> Cognição – 3 a 4 anos | C38: ='AV 2'!I83 -> 0 | D38: 24 | E38: =(C38*12)/D38 -> 0 | F38: =C38/D38 -> 0 | H38: ='AV 1'!K70 -> Auto cuidados – 3 a 4 anos | I38: ='AV 2'!L86 -> 0 | J38: 15 | K38: =(I38*12)/J38 -> 0 | L38: =I38/J38 -> 0
B39: ='AV 1'!H84 -> Cognição – 4 a 5 anos | C39: ='AV 2'!I107 -> 0 | D39: 22 | E39: =(C39*12)/D39 -> 0 | F39: =C39/D39 -> 0 | H39: ='AV 1'!K87 -> Auto cuidados – 4 a 5 anos | I39: ='AV 2'!L111 -> 0 | J39: 23 | K39: =(I39*12)/J39 -> 0 | L39: =I39/J39 -> 0
B40: ='AV 1'!H108 -> Cognição – 5 a 6 anos | C40: ='AV 2'!I131 -> 0 | D40: 22 | E40: =(C40*12)/D40 -> 0 | F40: =C40/D40 -> 0 | H40: ='AV 1'!K112 -> Auto cuidados – 5 a 6 anos | I40: ='AV 2'!L128 -> 0 | J40: 15 | K40: =(I40*12)/J40 -> 0 | L40: =I40/J40 -> 0
B41: TOTAL | C41: =SUM(C35:C40) -> 0 | D41: =SUM(D35:D40) -> 108 | E41: =SUM(E35:E40) -> 0 | F41: =C41/D41 -> 0 | H41: TOTAL | I41: =SUM(I35:I40) -> 0 | J41: =SUM(J35:J40) -> 105 | K41: =SUM(K35:K40) -> 0 | L41: =I41/J41 -> 0
B42: IDADE DA CRIANÇA - COGNIÇÃO | E42: =E41/12 -> 0 | H42: IDADE DA CRIANÇA - AUTOCUIDADOS | K42: =K41/12 -> 0
B44: DESENVOLVIMENTO MOTOR | C44: Pontuação (Acertos) | D44: Pontuação Esperada | E44: Idade | F44: % Acertos
B45: ='AV 1'!N12 -> Desenvolvimento Motor – 0 a 1 ano | C45: ='AV 2'!O58 -> 0 | D45: 45 | E45: =(C45*12)/D45 -> 0 | F45: =C45/D45 -> 0
B46: ='AV 1'!N59 -> Desenvolvimento Motor – 1 a 2 anos | C46: ='AV 2'!O78 -> 0 | D46: 18 | E46: =(C46*12)/D46 -> 0 | F46: =C46/D46 -> 0
B47: ='AV 1'!N79 -> Desenvolvimento Motor – 2 a 3 anos | C47: ='AV 2'!O97 -> 0 | D47: 17 | E47: =(C47*12)/D47 -> 0 | F47: =C47/D47 -> 0
B48: ='AV 1'!N98 -> Desenvolvimento Motor – 3 a 4 ano | C48: ='AV 2'!O114 -> 0 | D48: 15 | E48: =(C48*12)/D48 -> 0 | F48: =C48/D48 -> 0
B49: ='AV 1'!N115 -> Desenvolvimento Motor – 4 a 5 anos | C49: ='AV 2'!O132 -> 0 | D49: 16 | E49: =(C49*12)/D49 -> 0 | F49: =C49/D49 -> 0
...

Sheet PEI AV 2
B2: GUIA PORTAGE DE EDUCAÇÃO PRÉ-ESCOLAR
B4: Nome:
B5: Idade: | C5: 6
B6: Avaliador:
B7: Data da Avaliação:
B9: * A tabela abaixo é automática, não sendo necessário o preenchimento. Filtre primeiro Objetivos Prioritários, retire o filtro, e faça novo filtro em Demais Objetivos.
B10: PLANO DE ENSINO INDIVIDUALIZADO
B11: OBJETIVOS PRIORITÁRIOS | C11: DEMAIS OBJETIVOS
B12: SOCIALIZAÇÃO | C12: SOCIALIZAÇÃO
B13: =IF('AV 2'!C13="Às vezes",'AV 2'!B13,"-") -> - | C13: =IF('AV 2'!C13="Não",'AV 2'!B13,"-") -> -
B14: =IF('AV 2'!C14="Às vezes",'AV 2'!B14,"-") -> - | C14: =IF('AV 2'!C14="Não",'AV 2'!B14,"-") -> 02 Sorri em resposta à atenção do adulto
B15: =IF('AV 2'!C15="Às vezes",'AV 2'!B15,"-") -> 03 Vocaliza em resposta à atenção | C15: =IF('AV 2'!C15="Não",'AV 2'!B15,"-") -> -
B16: =IF('AV 2'!C16="Às vezes",'AV 2'!B16,"-") -> - | C16: =IF('AV 2'!C16="Não",'AV 2'!B16,"-") -> -
B17: =IF('AV 2'!C17="Às vezes",'AV 2'!B17,"-") -> - | C17: =IF('AV 2'!C17="Não",'AV 2'!B17,"-") -> -
B18: =IF('AV 2'!C18="Às vezes",'AV 2'!B18,"-") -> - | C18: =IF('AV 2'!C18="Não",'AV 2'!B18,"-") -> -
B19: =IF('AV 2'!C19="Às vezes",'AV 2'!B19,"-") -> - | C19: =IF('AV 2'!C19="Não",'AV 2'!B19,"-") -> -
B20: =IF('AV 2'!C20="Às vezes",'AV 2'!B20,"-") -> - | C20: =IF('AV 2'!C20="Não",'AV 2'!B20,"-") -> -
B21: =IF('AV 2'!C21="Às vezes",'AV 2'!B21,"-") -> - | C21: =IF('AV 2'!C21="Não",'AV 2'!B21,"-") -> -
B22: =IF('AV 2'!C22="Às vezes",'AV 2'!B22,"-") -> - | C22: =IF('AV 2'!C22="Não",'AV 2'!B22,"-") -> -
B23: =IF('AV 2'!C23="Às vezes",'AV 2'!B23,"-") -> - | C23: =IF('AV 2'!C23="Não",'AV 2'!B23,"-") -> -
B24: =IF('AV 2'!C24="Às vezes",'AV 2'!B24,"-") -> - | C24: =IF('AV 2'!C24="Não",'AV 2'!B24,"-") -> -
... B105: =IF('AV 2'!C105="Às vezes",'AV 2'!B105,"-") -> - | C105: =IF('AV 2'!C105="Não",'AV 2'!B105,"-") -> -
B106: LINGUAGEM | C106: LINGUAGEM
B107: =IF('AV 2'!F13="Às vezes",'AV 2'!E13,"-") -> - | C107: =IF('AV 2'!F13="Não",'AV 2'!E13,"-") -> -
B108: =IF('AV 2'!F14="Às vezes",'AV 2'!E14,"-") -> - | C108: =IF('AV 2'!F14="Não",'AV 2'!E14,"-") -> -
B109: =IF('AV 2'!F15="Às vezes",'AV 2'!E15,"-") -> - | C109: =IF('AV 2'!F15="Não",'AV 2'!E15,"-") -> -
B110: =IF('AV 2'!F16="Às vezes",'AV 2'!E16,"-") -> - | C110: =IF('AV 2'!F16="Não",'AV 2'!E16,"-") -> -
B111: =IF('AV 2'!F17="Às vezes",'AV 2'!E17,"-") -> - | C111: =IF('AV 2'!F17="Não",'AV 2'!E17,"-") -> -
B112: =IF('AV 2'!F18="Às vezes",'AV 2'!E18,"-") -> - | C112: =IF('AV 2'!F18="Não",'AV 2'!E18,"-") -> -
B113: =IF('AV 2'!F19="Às vezes",'AV 2'!E19,"-") -> - | C113: =IF('AV 2'!F19="Não",'AV 2'!E19,"-") -> -
B114: =IF('AV 2'!F20="Às vezes",'AV 2'!E20,"-") -> - | C114: =IF('AV 2'!F20="Não",'AV 2'!E20,"-") -> -
B115: =IF('AV 2'!F21="Às vezes",'AV 2'!E21,"-") -> - | C115: =IF('AV 2'!F21="Não",'AV 2'!E21,"-") -> -
B116: =IF('AV 2'!F22="Às vezes",'AV 2'!E22,"-") -> - | C116: =IF('AV 2'!F22="Não",'AV 2'!E22,"-") -> -
B117: =IF('AV 2'!F23="Às vezes",'AV 2'!E23,"-") -> - | C117: =IF('AV 2'!F23="Não",'AV 2'!E23,"-") -> -
B118: =IF('AV 2'!F24="Às vezes",'AV 2'!E24,"-") -> - | C118: =IF('AV 2'!F24="Não",'AV 2'!E24,"-") -> -
... B215: =IF('AV 2'!F121="Às vezes",'AV 2'!E121,"-") -> - | C215: =IF('AV 2'!F121="Não",'AV 2'!E121,"-") -> -
B216: COGNIÇÃO | C216: COGNIÇÃO
B217: =IF('AV 2'!I13="Às vezes",'AV 2'!H13,"-") -> - | C217: =IF('AV 2'!I13="Não",'AV 2'!H13,"-") -> -
B218: =IF('AV 2'!I14="Às vezes",'AV 2'!H14,"-") -> - | C218: =IF('AV 2'!I14="Não",'AV 2'!H14,"-") -> -
B219: =IF('AV 2'!I15="Às vezes",'AV 2'!H15,"-") -> - | C219: =IF('AV 2'!I15="Não",'AV 2'!H15,"-") -> -
...

Sheet AV 3
B2: GUIA PORTAGE DE EDUCAÇÃO PRÉ-ESCOLAR
B4: Nome: | C4: JY Silva
B5: Idade: (insira apenas o número) | C5: 6
B6: Avaliador: | C6: Maria Luiza
B7: Data da Avaliação: | C7: 45737
B9: * Nas tabelas abaixo, insira apenas SIM, NÃO e ÀS VEZES QUE CONSTAM NA LISTA DE OPÇÕES DE CADA CÉLULA. Não digite texto algum, apenas selecione a opção da lista. Os totais e pontos são automáticos.
